<?xml version="1.0"?>
<robot name="my_robot">

    <material name="gray"><color rgba="0.7 0.7 0.7 1" /></material>
    <material name="green"><color rgba="0 0.6 0 1" /></material>
    <material name="white"><color rgba="1 1 1 1" /></material>

    <link name="base_link">
        <visual>
            <origin xyz="0 0 0.1" rpy="0 0 0" />
            <geometry><box size="0.6 0.4 0.2"/></geometry>
            <material name="green" />
        </visual>
        <collision>
            <origin xyz="0 0 0.1" rpy="0 0 0" />
            <geometry><box size="0.6 0.4 0.2"/></geometry>
        </collision>
        <inertial>
            <origin xyz="0 0 0.1" rpy="0 0 0"/><mass value="5.0"/>
            <inertia ixx="0.083" ixy="0" ixz="0" iyy="0.166" iyz="0" izz="0.216"/>
        </inertial>
    </link>

    <link name="lider">
        <visual>
            <geometry><cylinder radius="0.1" length="0.05" /></geometry>
            <material name="white" />
        </visual>
        <collision>
            <geometry><cylinder radius="0.1" length="0.05" /></geometry>
        </collision>
        <inertial><mass value="0.1"/><inertia ixx="0.00027" ixy="0" ixz="0" iyy="0.00027" iyz="0" izz="0.0005"/></inertial>
    </link>

    <link name="left_wheel">
        <visual>
            <geometry><cylinder radius="0.1" length="0.05" /></geometry>
            <origin xyz="0 0 0" rpy="1.57 0 0" /><material name="white" />
        </visual>
        <collision>
            <geometry><cylinder radius="0.1" length="0.05" /></geometry>
            <origin xyz="0 0 0" rpy="1.57 0 0" />
        </collision>
        <inertial><mass value="0.5"/><inertia ixx="0.00135" ixy="0" ixz="0" iyy="0.00135" iyz="0" izz="0.0025"/></inertial>
    </link>

    <link name="right_wheel">
        <visual>
            <geometry><cylinder radius="0.1" length="0.05" /></geometry>
            <origin xyz="0 0 0" rpy="1.57 0 0" /><material name="white" />
        </visual>
        <collision>
            <geometry><cylinder radius="0.1" length="0.05" /></geometry>
            <origin xyz="0 0 0" rpy="1.57 0 0" />
        </collision>
        <inertial><mass value="0.5"/><inertia ixx="0.00135" ixy="0" ixz="0" iyy="0.00135" iyz="0" izz="0.0025"/></inertial>
    </link>

    <link name="caster_wheel">
        <visual>
            <geometry><sphere radius="0.1" /></geometry>
            <material name="gray" />
        </visual>
        <collision>
            <geometry><sphere radius="0.1" /></geometry>
        </collision>
        <inertial><mass value="0.2"/><inertia ixx="0.0008" ixy="0" ixz="0" iyy="0.0008" iyz="0" izz="0.0008"/></inertial>
    </link>

    <joint name="base_lider_joint" type="fixed">
        <parent link="base_link" /><child link="lider" /><origin xyz="0 0 0.225" rpy="0 0 0" />
    </joint>

    <joint name="base_left_wheel_joint" type="continuous">
        <parent link="base_link" /><child link="left_wheel" /><origin xyz="-0.25 0.25 0.1" rpy="0 0 0" /><axis xyz="0 1 0" />
    </joint> 

    <joint name="base_right_wheel_joint" type="continuous">
        <parent link="base_link" /><child link="right_wheel" /><origin xyz="-0.25 -0.25 0.1" rpy="0 0 0" /><axis xyz="0 1 0" />
    </joint> 

    <joint name="base_caster_wheel_joint" type="fixed">
        <parent link="base_link" /><child link="caster_wheel" /><origin xyz="0.25 0 0.1" rpy="0 0 0" />
    </joint>

    <gazebo>
        <plugin filename="gz-sim-diff-drive-system" name="gz::sim::systems::DiffDrive">
            <left_joint>base_left_wheel_joint</left_joint>
            <right_joint>base_right_wheel_joint</right_joint>
            <wheel_separation>0.5</wheel_separation>
            <wheel_radius>0.1</wheel_radius>
            <topic>cmd_vel</topic>
            <odom_topic>odom</odom_topic>
            <frame_id>odom</frame_id>
            <child_frame_id>base_link</child_frame_id>
        </plugin>

        <plugin filename="gz-sim-joint-state-publisher-system" name="gz::sim::systems::JointStatePublisher"/>
    </gazebo>

    <gazebo reference="lider">
        <sensor name='gpu_lidar' type='gpu_lidar'>
            <gz_frame_id>lider</gz_frame_id>
            <update_rate>10</update_rate>
            <topic>scan</topic>
            <lidar>
                <scan>
                    <horizontal>
                        <samples>360</samples>
                        <min_angle>-3.14</min_angle>
                        <max_angle>3.14</max_angle>
                    </horizontal>
                </scan>
                <range><min>0.1</min><max>12.0</max></range>
            </lidar>
            <visualize>true</visualize>
        </sensor>
    </gazebo>

</robot>
